[2025-07-23T08:43:47.530+0000] {taskinstance.py:1956} INFO - Dependencies all met for dep_context=non-requeueable deps ti=<TaskInstance: openaq_mexico_air_quality_etl.extract_transform_load_openaq_mex scheduled__2025-07-22T03:00:00+00:00 [queued]>
[2025-07-23T08:43:47.536+0000] {taskinstance.py:1956} INFO - Dependencies all met for dep_context=requeueable deps ti=<TaskInstance: openaq_mexico_air_quality_etl.extract_transform_load_openaq_mex scheduled__2025-07-22T03:00:00+00:00 [queued]>
[2025-07-23T08:43:47.536+0000] {taskinstance.py:2170} INFO - Starting attempt 2 of 2
[2025-07-23T08:43:47.544+0000] {taskinstance.py:2191} INFO - Executing <Task(PythonOperator): extract_transform_load_openaq_mex> on 2025-07-22 03:00:00+00:00
[2025-07-23T08:43:47.549+0000] {standard_task_runner.py:60} INFO - Started process 559 to run task
[2025-07-23T08:43:47.553+0000] {standard_task_runner.py:87} INFO - Running: ['***', 'tasks', 'run', 'openaq_mexico_air_quality_etl', 'extract_transform_load_openaq_mex', 'scheduled__2025-07-22T03:00:00+00:00', '--job-id', '32', '--raw', '--subdir', 'DAGS_FOLDER/MexicoairQ_etl_dag.py', '--cfg-path', '/tmp/tmp4osneww3']
[2025-07-23T08:43:47.557+0000] {standard_task_runner.py:88} INFO - Job 32: Subtask extract_transform_load_openaq_mex
[2025-07-23T08:43:47.614+0000] {task_command.py:423} INFO - Running <TaskInstance: openaq_mexico_air_quality_etl.extract_transform_load_openaq_mex scheduled__2025-07-22T03:00:00+00:00 [running]> on host 254e02a0caf4
[2025-07-23T08:43:47.677+0000] {taskinstance.py:2480} INFO - Exporting env vars: AIRFLOW_CTX_DAG_OWNER='***' AIRFLOW_CTX_DAG_ID='openaq_mexico_air_quality_etl' AIRFLOW_CTX_TASK_ID='extract_transform_load_openaq_mex' AIRFLOW_CTX_EXECUTION_DATE='2025-07-22T03:00:00+00:00' AIRFLOW_CTX_TRY_NUMBER='2' AIRFLOW_CTX_DAG_RUN_ID='scheduled__2025-07-22T03:00:00+00:00'
[2025-07-23T08:43:47.855+0000] {taskinstance.py:2698} ERROR - Task failed with exception
Traceback (most recent call last):
  File "/home/airflow/.local/lib/python3.10/site-packages/airflow/models/taskinstance.py", line 433, in _execute_task
    result = execute_callable(context=context, **execute_callable_kwargs)
  File "/home/airflow/.local/lib/python3.10/site-packages/airflow/operators/python.py", line 199, in execute
    return_value = self.execute_callable()
  File "/home/airflow/.local/lib/python3.10/site-packages/airflow/operators/python.py", line 216, in execute_callable
    return self.python_callable(*self.op_args, **self.op_kwargs)
  File "/opt/airflow/dags/MexicoairQ_etl_dag.py", line 15, in etl_openaq_mexico
    resp.raise_for_status()
  File "/home/airflow/.local/lib/python3.10/site-packages/requests/models.py", line 1021, in raise_for_status
    raise HTTPError(http_error_msg, response=self)
requests.exceptions.HTTPError: 410 Client Error: Gone for url: https://api.openaq.org/v2/latest?country=MX&limit=100
[2025-07-23T08:43:47.864+0000] {taskinstance.py:1138} INFO - Marking task as FAILED. dag_id=openaq_mexico_air_quality_etl, task_id=extract_transform_load_openaq_mex, execution_date=20250722T030000, start_date=20250723T084347, end_date=20250723T084347
[2025-07-23T08:43:47.873+0000] {standard_task_runner.py:107} ERROR - Failed to execute job 32 for task extract_transform_load_openaq_mex (410 Client Error: Gone for url: https://api.openaq.org/v2/latest?country=MX&limit=100; 559)
[2025-07-23T08:43:47.888+0000] {local_task_job_runner.py:234} INFO - Task exited with return code 1
[2025-07-23T08:43:47.902+0000] {taskinstance.py:3280} INFO - 0 downstream tasks scheduled from follow-on schedule check
