[2025-07-23T09:35:39.373+0000] {taskinstance.py:1956} INFO - Dependencies all met for dep_context=non-requeueable deps ti=<TaskInstance: rest_countries_dag.fetch_countries scheduled__2025-07-22T00:00:00+00:00 [queued]>
[2025-07-23T09:35:39.379+0000] {taskinstance.py:1956} INFO - Dependencies all met for dep_context=requeueable deps ti=<TaskInstance: rest_countries_dag.fetch_countries scheduled__2025-07-22T00:00:00+00:00 [queued]>
[2025-07-23T09:35:39.379+0000] {taskinstance.py:2170} INFO - Starting attempt 1 of 2
[2025-07-23T09:35:39.388+0000] {taskinstance.py:2191} INFO - Executing <Task(PythonOperator): fetch_countries> on 2025-07-22 00:00:00+00:00
[2025-07-23T09:35:39.394+0000] {standard_task_runner.py:60} INFO - Started process 4361 to run task
[2025-07-23T09:35:39.398+0000] {standard_task_runner.py:87} INFO - Running: ['***', 'tasks', 'run', 'rest_countries_dag', 'fetch_countries', 'scheduled__2025-07-22T00:00:00+00:00', '--job-id', '70', '--raw', '--subdir', 'DAGS_FOLDER/countries_etl_dag.py', '--cfg-path', '/tmp/tmp280dknto']
[2025-07-23T09:35:39.400+0000] {standard_task_runner.py:88} INFO - Job 70: Subtask fetch_countries
[2025-07-23T09:35:39.443+0000] {task_command.py:423} INFO - Running <TaskInstance: rest_countries_dag.fetch_countries scheduled__2025-07-22T00:00:00+00:00 [running]> on host 254e02a0caf4
[2025-07-23T09:35:39.499+0000] {taskinstance.py:2480} INFO - Exporting env vars: AIRFLOW_CTX_DAG_OWNER='***' AIRFLOW_CTX_DAG_ID='rest_countries_dag' AIRFLOW_CTX_TASK_ID='fetch_countries' AIRFLOW_CTX_EXECUTION_DATE='2025-07-22T00:00:00+00:00' AIRFLOW_CTX_TRY_NUMBER='1' AIRFLOW_CTX_DAG_RUN_ID='scheduled__2025-07-22T00:00:00+00:00'
[2025-07-23T09:35:39.793+0000] {taskinstance.py:2698} ERROR - Task failed with exception
Traceback (most recent call last):
  File "/home/airflow/.local/lib/python3.10/site-packages/airflow/models/taskinstance.py", line 433, in _execute_task
    result = execute_callable(context=context, **execute_callable_kwargs)
  File "/home/airflow/.local/lib/python3.10/site-packages/airflow/operators/python.py", line 199, in execute
    return_value = self.execute_callable()
  File "/home/airflow/.local/lib/python3.10/site-packages/airflow/operators/python.py", line 216, in execute_callable
    return self.python_callable(*self.op_args, **self.op_kwargs)
  File "/opt/airflow/dags/countries_etl_dag.py", line 16, in fetch_countries
    response.raise_for_status()
  File "/home/airflow/.local/lib/python3.10/site-packages/requests/models.py", line 1021, in raise_for_status
    raise HTTPError(http_error_msg, response=self)
requests.exceptions.HTTPError: 400 Client Error: Bad Request for url: https://restcountries.com/v3.1/all
[2025-07-23T09:35:39.801+0000] {taskinstance.py:1138} INFO - Marking task as UP_FOR_RETRY. dag_id=rest_countries_dag, task_id=fetch_countries, execution_date=20250722T000000, start_date=20250723T093539, end_date=20250723T093539
[2025-07-23T09:35:39.809+0000] {standard_task_runner.py:107} ERROR - Failed to execute job 70 for task fetch_countries (400 Client Error: Bad Request for url: https://restcountries.com/v3.1/all; 4361)
[2025-07-23T09:35:39.850+0000] {local_task_job_runner.py:234} INFO - Task exited with return code 1
[2025-07-23T09:35:39.864+0000] {taskinstance.py:3280} INFO - 0 downstream tasks scheduled from follow-on schedule check
