[2025-07-23T09:17:52.874+0000] {taskinstance.py:1956} INFO - Dependencies all met for dep_context=non-requeueable deps ti=<TaskInstance: bitcoin_price_dag.fetch_bitcoin_price manual__2025-07-23T09:12:50.560481+00:00 [queued]>
[2025-07-23T09:17:52.880+0000] {taskinstance.py:1956} INFO - Dependencies all met for dep_context=requeueable deps ti=<TaskInstance: bitcoin_price_dag.fetch_bitcoin_price manual__2025-07-23T09:12:50.560481+00:00 [queued]>
[2025-07-23T09:17:52.880+0000] {taskinstance.py:2170} INFO - Starting attempt 2 of 4
[2025-07-23T09:17:52.889+0000] {taskinstance.py:2191} INFO - Executing <Task(PythonOperator): fetch_bitcoin_price> on 2025-07-23 09:12:50.560481+00:00
[2025-07-23T09:17:52.895+0000] {standard_task_runner.py:60} INFO - Started process 3086 to run task
[2025-07-23T09:17:52.899+0000] {standard_task_runner.py:87} INFO - Running: ['***', 'tasks', 'run', 'bitcoin_price_dag', 'fetch_bitcoin_price', 'manual__2025-07-23T09:12:50.560481+00:00', '--job-id', '54', '--raw', '--subdir', 'DAGS_FOLDER/bitcoin_etl_dag.py', '--cfg-path', '/tmp/tmp_hhzl8_o']
[2025-07-23T09:17:52.901+0000] {standard_task_runner.py:88} INFO - Job 54: Subtask fetch_bitcoin_price
[2025-07-23T09:17:52.945+0000] {task_command.py:423} INFO - Running <TaskInstance: bitcoin_price_dag.fetch_bitcoin_price manual__2025-07-23T09:12:50.560481+00:00 [running]> on host 254e02a0caf4
[2025-07-23T09:17:53.003+0000] {taskinstance.py:2480} INFO - Exporting env vars: AIRFLOW_CTX_DAG_OWNER='***' AIRFLOW_CTX_DAG_ID='bitcoin_price_dag' AIRFLOW_CTX_TASK_ID='fetch_bitcoin_price' AIRFLOW_CTX_EXECUTION_DATE='2025-07-23T09:12:50.560481+00:00' AIRFLOW_CTX_TRY_NUMBER='2' AIRFLOW_CTX_DAG_RUN_ID='manual__2025-07-23T09:12:50.560481+00:00'
[2025-07-23T09:17:53.080+0000] {taskinstance.py:2698} ERROR - Task failed with exception
Traceback (most recent call last):
  File "/home/airflow/.local/lib/python3.10/site-packages/urllib3/connection.py", line 203, in _new_conn
    sock = connection.create_connection(
  File "/home/airflow/.local/lib/python3.10/site-packages/urllib3/util/connection.py", line 60, in create_connection
    for res in socket.getaddrinfo(host, port, family, socket.SOCK_STREAM):
  File "/usr/local/lib/python3.10/socket.py", line 955, in getaddrinfo
    for res in _socket.getaddrinfo(host, port, family, type, proto, flags):
socket.gaierror: [Errno -2] Name or service not known

The above exception was the direct cause of the following exception:

Traceback (most recent call last):
  File "/home/airflow/.local/lib/python3.10/site-packages/urllib3/connectionpool.py", line 791, in urlopen
    response = self._make_request(
  File "/home/airflow/.local/lib/python3.10/site-packages/urllib3/connectionpool.py", line 492, in _make_request
    raise new_e
  File "/home/airflow/.local/lib/python3.10/site-packages/urllib3/connectionpool.py", line 468, in _make_request
    self._validate_conn(conn)
  File "/home/airflow/.local/lib/python3.10/site-packages/urllib3/connectionpool.py", line 1097, in _validate_conn
    conn.connect()
  File "/home/airflow/.local/lib/python3.10/site-packages/urllib3/connection.py", line 611, in connect
    self.sock = sock = self._new_conn()
  File "/home/airflow/.local/lib/python3.10/site-packages/urllib3/connection.py", line 210, in _new_conn
    raise NameResolutionError(self.host, self, e) from e
urllib3.exceptions.NameResolutionError: <urllib3.connection.HTTPSConnection object at 0x7bc7ce6d7520>: Failed to resolve 'api.coindesk.com' ([Errno -2] Name or service not known)

The above exception was the direct cause of the following exception:

Traceback (most recent call last):
  File "/home/airflow/.local/lib/python3.10/site-packages/requests/adapters.py", line 486, in send
    resp = conn.urlopen(
  File "/home/airflow/.local/lib/python3.10/site-packages/urllib3/connectionpool.py", line 845, in urlopen
    retries = retries.increment(
  File "/home/airflow/.local/lib/python3.10/site-packages/urllib3/util/retry.py", line 515, in increment
    raise MaxRetryError(_pool, url, reason) from reason  # type: ignore[arg-type]
urllib3.exceptions.MaxRetryError: HTTPSConnectionPool(host='api.coindesk.com', port=443): Max retries exceeded with url: /v1/bpi/currentprice/USD.json (Caused by NameResolutionError("<urllib3.connection.HTTPSConnection object at 0x7bc7ce6d7520>: Failed to resolve 'api.coindesk.com' ([Errno -2] Name or service not known)"))

During handling of the above exception, another exception occurred:

Traceback (most recent call last):
  File "/home/airflow/.local/lib/python3.10/site-packages/airflow/models/taskinstance.py", line 433, in _execute_task
    result = execute_callable(context=context, **execute_callable_kwargs)
  File "/home/airflow/.local/lib/python3.10/site-packages/airflow/operators/python.py", line 199, in execute
    return_value = self.execute_callable()
  File "/home/airflow/.local/lib/python3.10/site-packages/airflow/operators/python.py", line 216, in execute_callable
    return self.python_callable(*self.op_args, **self.op_kwargs)
  File "/opt/airflow/dags/bitcoin_etl_dag.py", line 15, in fetch_bitcoin_price
    response = requests.get(api_url)
  File "/home/airflow/.local/lib/python3.10/site-packages/requests/api.py", line 73, in get
    return request("get", url, params=params, **kwargs)
  File "/home/airflow/.local/lib/python3.10/site-packages/requests/api.py", line 59, in request
    return session.request(method=method, url=url, **kwargs)
  File "/home/airflow/.local/lib/python3.10/site-packages/requests/sessions.py", line 589, in request
    resp = self.send(prep, **send_kwargs)
  File "/home/airflow/.local/lib/python3.10/site-packages/requests/sessions.py", line 703, in send
    r = adapter.send(request, **kwargs)
  File "/home/airflow/.local/lib/python3.10/site-packages/requests/adapters.py", line 519, in send
    raise ConnectionError(e, request=request)
requests.exceptions.ConnectionError: HTTPSConnectionPool(host='api.coindesk.com', port=443): Max retries exceeded with url: /v1/bpi/currentprice/USD.json (Caused by NameResolutionError("<urllib3.connection.HTTPSConnection object at 0x7bc7ce6d7520>: Failed to resolve 'api.coindesk.com' ([Errno -2] Name or service not known)"))
[2025-07-23T09:17:53.091+0000] {taskinstance.py:1138} INFO - Marking task as UP_FOR_RETRY. dag_id=bitcoin_price_dag, task_id=fetch_bitcoin_price, execution_date=20250723T091250, start_date=20250723T091752, end_date=20250723T091753
[2025-07-23T09:17:53.098+0000] {standard_task_runner.py:107} ERROR - Failed to execute job 54 for task fetch_bitcoin_price (HTTPSConnectionPool(host='api.coindesk.com', port=443): Max retries exceeded with url: /v1/bpi/currentprice/USD.json (Caused by NameResolutionError("<urllib3.connection.HTTPSConnection object at 0x7bc7ce6d7520>: Failed to resolve 'api.coindesk.com' ([Errno -2] Name or service not known)")); 3086)
[2025-07-23T09:17:53.111+0000] {local_task_job_runner.py:234} INFO - Task exited with return code 1
[2025-07-23T09:17:53.125+0000] {taskinstance.py:3280} INFO - 0 downstream tasks scheduled from follow-on schedule check
