[2025-07-23T09:36:17.556+0000] {taskinstance.py:1956} INFO - Dependencies all met for dep_context=non-requeueable deps ti=<TaskInstance: rest_countries_dag.fetch_countries manual__2025-07-23T09:36:16.553895+00:00 [queued]>
[2025-07-23T09:36:17.562+0000] {taskinstance.py:1956} INFO - Dependencies all met for dep_context=requeueable deps ti=<TaskInstance: rest_countries_dag.fetch_countries manual__2025-07-23T09:36:16.553895+00:00 [queued]>
[2025-07-23T09:36:17.562+0000] {taskinstance.py:2170} INFO - Starting attempt 1 of 2
[2025-07-23T09:36:17.570+0000] {taskinstance.py:2191} INFO - Executing <Task(PythonOperator): fetch_countries> on 2025-07-23 09:36:16.553895+00:00
[2025-07-23T09:36:17.576+0000] {standard_task_runner.py:60} INFO - Started process 4428 to run task
[2025-07-23T09:36:17.580+0000] {standard_task_runner.py:87} INFO - Running: ['***', 'tasks', 'run', 'rest_countries_dag', 'fetch_countries', 'manual__2025-07-23T09:36:16.553895+00:00', '--job-id', '74', '--raw', '--subdir', 'DAGS_FOLDER/countries_etl_dag.py', '--cfg-path', '/tmp/tmpbguousy7']
[2025-07-23T09:36:17.582+0000] {standard_task_runner.py:88} INFO - Job 74: Subtask fetch_countries
[2025-07-23T09:36:17.623+0000] {task_command.py:423} INFO - Running <TaskInstance: rest_countries_dag.fetch_countries manual__2025-07-23T09:36:16.553895+00:00 [running]> on host 254e02a0caf4
[2025-07-23T09:36:17.677+0000] {taskinstance.py:2480} INFO - Exporting env vars: AIRFLOW_CTX_DAG_OWNER='***' AIRFLOW_CTX_DAG_ID='rest_countries_dag' AIRFLOW_CTX_TASK_ID='fetch_countries' AIRFLOW_CTX_EXECUTION_DATE='2025-07-23T09:36:16.553895+00:00' AIRFLOW_CTX_TRY_NUMBER='1' AIRFLOW_CTX_DAG_RUN_ID='manual__2025-07-23T09:36:16.553895+00:00'
[2025-07-23T09:36:17.969+0000] {taskinstance.py:2698} ERROR - Task failed with exception
Traceback (most recent call last):
  File "/home/airflow/.local/lib/python3.10/site-packages/airflow/models/taskinstance.py", line 433, in _execute_task
    result = execute_callable(context=context, **execute_callable_kwargs)
  File "/home/airflow/.local/lib/python3.10/site-packages/airflow/operators/python.py", line 199, in execute
    return_value = self.execute_callable()
  File "/home/airflow/.local/lib/python3.10/site-packages/airflow/operators/python.py", line 216, in execute_callable
    return self.python_callable(*self.op_args, **self.op_kwargs)
  File "/opt/airflow/dags/countries_etl_dag.py", line 16, in fetch_countries
    response.raise_for_status()
  File "/home/airflow/.local/lib/python3.10/site-packages/requests/models.py", line 1021, in raise_for_status
    raise HTTPError(http_error_msg, response=self)
requests.exceptions.HTTPError: 400 Client Error: Bad Request for url: https://restcountries.com/v3.1/all
[2025-07-23T09:36:17.977+0000] {taskinstance.py:1138} INFO - Marking task as UP_FOR_RETRY. dag_id=rest_countries_dag, task_id=fetch_countries, execution_date=20250723T093616, start_date=20250723T093617, end_date=20250723T093617
[2025-07-23T09:36:17.984+0000] {standard_task_runner.py:107} ERROR - Failed to execute job 74 for task fetch_countries (400 Client Error: Bad Request for url: https://restcountries.com/v3.1/all; 4428)
[2025-07-23T09:36:18.032+0000] {local_task_job_runner.py:234} INFO - Task exited with return code 1
[2025-07-23T09:36:18.046+0000] {taskinstance.py:3280} INFO - 0 downstream tasks scheduled from follow-on schedule check
