[2025-07-23T09:29:40.247+0000] {taskinstance.py:1956} INFO - Dependencies all met for dep_context=non-requeueable deps ti=<TaskInstance: etl_rest_countries.extract manual__2025-07-23T09:29:39.439379+00:00 [queued]>
[2025-07-23T09:29:40.255+0000] {taskinstance.py:1956} INFO - Dependencies all met for dep_context=requeueable deps ti=<TaskInstance: etl_rest_countries.extract manual__2025-07-23T09:29:39.439379+00:00 [queued]>
[2025-07-23T09:29:40.255+0000] {taskinstance.py:2170} INFO - Starting attempt 1 of 1
[2025-07-23T09:29:40.267+0000] {taskinstance.py:2191} INFO - Executing <Task(PythonOperator): extract> on 2025-07-23 09:29:39.439379+00:00
[2025-07-23T09:29:40.274+0000] {standard_task_runner.py:60} INFO - Started process 3899 to run task
[2025-07-23T09:29:40.279+0000] {standard_task_runner.py:87} INFO - Running: ['***', 'tasks', 'run', 'etl_rest_countries', 'extract', 'manual__2025-07-23T09:29:39.439379+00:00', '--job-id', '65', '--raw', '--subdir', 'DAGS_FOLDER/countries_etl_dag.py', '--cfg-path', '/tmp/tmpwzdtyrsl']
[2025-07-23T09:29:40.281+0000] {standard_task_runner.py:88} INFO - Job 65: Subtask extract
[2025-07-23T09:29:40.330+0000] {task_command.py:423} INFO - Running <TaskInstance: etl_rest_countries.extract manual__2025-07-23T09:29:39.439379+00:00 [running]> on host 254e02a0caf4
[2025-07-23T09:29:40.388+0000] {taskinstance.py:2480} INFO - Exporting env vars: AIRFLOW_CTX_DAG_OWNER='***' AIRFLOW_CTX_DAG_ID='etl_rest_countries' AIRFLOW_CTX_TASK_ID='extract' AIRFLOW_CTX_EXECUTION_DATE='2025-07-23T09:29:39.439379+00:00' AIRFLOW_CTX_TRY_NUMBER='1' AIRFLOW_CTX_DAG_RUN_ID='manual__2025-07-23T09:29:39.439379+00:00'
[2025-07-23T09:29:40.671+0000] {taskinstance.py:2698} ERROR - Task failed with exception
Traceback (most recent call last):
  File "/home/airflow/.local/lib/python3.10/site-packages/airflow/models/taskinstance.py", line 433, in _execute_task
    result = execute_callable(context=context, **execute_callable_kwargs)
  File "/home/airflow/.local/lib/python3.10/site-packages/airflow/operators/python.py", line 199, in execute
    return_value = self.execute_callable()
  File "/home/airflow/.local/lib/python3.10/site-packages/airflow/operators/python.py", line 216, in execute_callable
    return self.python_callable(*self.op_args, **self.op_kwargs)
  File "/opt/airflow/dags/countries_etl_dag.py", line 11, in extract_countries
    response.raise_for_status()
  File "/home/airflow/.local/lib/python3.10/site-packages/requests/models.py", line 1021, in raise_for_status
    raise HTTPError(http_error_msg, response=self)
requests.exceptions.HTTPError: 400 Client Error: Bad Request for url: https://restcountries.com/v3.1/all
[2025-07-23T09:29:40.680+0000] {taskinstance.py:1138} INFO - Marking task as FAILED. dag_id=etl_rest_countries, task_id=extract, execution_date=20250723T092939, start_date=20250723T092940, end_date=20250723T092940
[2025-07-23T09:29:40.688+0000] {standard_task_runner.py:107} ERROR - Failed to execute job 65 for task extract (400 Client Error: Bad Request for url: https://restcountries.com/v3.1/all; 3899)
[2025-07-23T09:29:40.732+0000] {local_task_job_runner.py:234} INFO - Task exited with return code 1
[2025-07-23T09:29:40.753+0000] {taskinstance.py:3280} INFO - 0 downstream tasks scheduled from follow-on schedule check
