[2025-07-23T09:29:44.121+0000] {taskinstance.py:1956} INFO - Dependencies all met for dep_context=non-requeueable deps ti=<TaskInstance: etl_open_library.extract manual__2025-07-23T09:29:43.814545+00:00 [queued]>
[2025-07-23T09:29:44.127+0000] {taskinstance.py:1956} INFO - Dependencies all met for dep_context=requeueable deps ti=<TaskInstance: etl_open_library.extract manual__2025-07-23T09:29:43.814545+00:00 [queued]>
[2025-07-23T09:29:44.127+0000] {taskinstance.py:2170} INFO - Starting attempt 1 of 1
[2025-07-23T09:29:44.136+0000] {taskinstance.py:2191} INFO - Executing <Task(PythonOperator): extract> on 2025-07-23 09:29:43.814545+00:00
[2025-07-23T09:29:44.143+0000] {standard_task_runner.py:60} INFO - Started process 3912 to run task
[2025-07-23T09:29:44.147+0000] {standard_task_runner.py:87} INFO - Running: ['***', 'tasks', 'run', 'etl_open_library', 'extract', 'manual__2025-07-23T09:29:43.814545+00:00', '--job-id', '69', '--raw', '--subdir', 'DAGS_FOLDER/library_etl_dag.py', '--cfg-path', '/tmp/tmp3ujt8o5q']
[2025-07-23T09:29:44.149+0000] {standard_task_runner.py:88} INFO - Job 69: Subtask extract
[2025-07-23T09:29:44.194+0000] {task_command.py:423} INFO - Running <TaskInstance: etl_open_library.extract manual__2025-07-23T09:29:43.814545+00:00 [running]> on host 254e02a0caf4
[2025-07-23T09:29:44.253+0000] {taskinstance.py:2480} INFO - Exporting env vars: AIRFLOW_CTX_DAG_OWNER='***' AIRFLOW_CTX_DAG_ID='etl_open_library' AIRFLOW_CTX_TASK_ID='extract' AIRFLOW_CTX_EXECUTION_DATE='2025-07-23T09:29:43.814545+00:00' AIRFLOW_CTX_TRY_NUMBER='1' AIRFLOW_CTX_DAG_RUN_ID='manual__2025-07-23T09:29:43.814545+00:00'
[2025-07-23T09:29:44.765+0000] {taskinstance.py:2698} ERROR - Task failed with exception
Traceback (most recent call last):
  File "/home/airflow/.local/lib/python3.10/site-packages/airflow/models/taskinstance.py", line 433, in _execute_task
    result = execute_callable(context=context, **execute_callable_kwargs)
  File "/home/airflow/.local/lib/python3.10/site-packages/airflow/operators/python.py", line 199, in execute
    return_value = self.execute_callable()
  File "/home/airflow/.local/lib/python3.10/site-packages/airflow/operators/python.py", line 216, in execute_callable
    return self.python_callable(*self.op_args, **self.op_kwargs)
  File "/opt/airflow/dags/library_etl_dag.py", line 13, in extract_books
    with open('/tmp/data/books_raw.json', 'w') as f:
FileNotFoundError: [Errno 2] No such file or directory: '/tmp/data/books_raw.json'
[2025-07-23T09:29:44.774+0000] {taskinstance.py:1138} INFO - Marking task as FAILED. dag_id=etl_open_library, task_id=extract, execution_date=20250723T092943, start_date=20250723T092944, end_date=20250723T092944
[2025-07-23T09:29:44.788+0000] {standard_task_runner.py:107} ERROR - Failed to execute job 69 for task extract ([Errno 2] No such file or directory: '/tmp/data/books_raw.json'; 3912)
[2025-07-23T09:29:44.804+0000] {local_task_job_runner.py:234} INFO - Task exited with return code 1
[2025-07-23T09:29:44.822+0000] {taskinstance.py:3280} INFO - 0 downstream tasks scheduled from follow-on schedule check
