[2025-07-23T09:40:54.699+0000] {taskinstance.py:1956} INFO - Dependencies all met for dep_context=non-requeueable deps ti=<TaskInstance: rest_countries_dag.fetch_countries manual__2025-07-23T09:35:52.688195+00:00 [queued]>
[2025-07-23T09:40:54.704+0000] {taskinstance.py:1956} INFO - Dependencies all met for dep_context=requeueable deps ti=<TaskInstance: rest_countries_dag.fetch_countries manual__2025-07-23T09:35:52.688195+00:00 [queued]>
[2025-07-23T09:40:54.704+0000] {taskinstance.py:2170} INFO - Starting attempt 2 of 2
[2025-07-23T09:40:54.711+0000] {taskinstance.py:2191} INFO - Executing <Task(PythonOperator): fetch_countries> on 2025-07-23 09:35:52.688195+00:00
[2025-07-23T09:40:54.717+0000] {standard_task_runner.py:60} INFO - Started process 4796 to run task
[2025-07-23T09:40:54.721+0000] {standard_task_runner.py:87} INFO - Running: ['***', 'tasks', 'run', 'rest_countries_dag', 'fetch_countries', 'manual__2025-07-23T09:35:52.688195+00:00', '--job-id', '76', '--raw', '--subdir', 'DAGS_FOLDER/countries_etl_dag.py', '--cfg-path', '/tmp/tmpun3yeawu']
[2025-07-23T09:40:54.723+0000] {standard_task_runner.py:88} INFO - Job 76: Subtask fetch_countries
[2025-07-23T09:40:54.762+0000] {task_command.py:423} INFO - Running <TaskInstance: rest_countries_dag.fetch_countries manual__2025-07-23T09:35:52.688195+00:00 [running]> on host 254e02a0caf4
[2025-07-23T09:40:54.815+0000] {taskinstance.py:2480} INFO - Exporting env vars: AIRFLOW_CTX_DAG_OWNER='***' AIRFLOW_CTX_DAG_ID='rest_countries_dag' AIRFLOW_CTX_TASK_ID='fetch_countries' AIRFLOW_CTX_EXECUTION_DATE='2025-07-23T09:35:52.688195+00:00' AIRFLOW_CTX_TRY_NUMBER='2' AIRFLOW_CTX_DAG_RUN_ID='manual__2025-07-23T09:35:52.688195+00:00'
[2025-07-23T09:40:55.110+0000] {taskinstance.py:2698} ERROR - Task failed with exception
Traceback (most recent call last):
  File "/home/airflow/.local/lib/python3.10/site-packages/airflow/models/taskinstance.py", line 433, in _execute_task
    result = execute_callable(context=context, **execute_callable_kwargs)
  File "/home/airflow/.local/lib/python3.10/site-packages/airflow/operators/python.py", line 199, in execute
    return_value = self.execute_callable()
  File "/home/airflow/.local/lib/python3.10/site-packages/airflow/operators/python.py", line 216, in execute_callable
    return self.python_callable(*self.op_args, **self.op_kwargs)
  File "/opt/airflow/dags/countries_etl_dag.py", line 16, in fetch_countries
    response.raise_for_status()
  File "/home/airflow/.local/lib/python3.10/site-packages/requests/models.py", line 1021, in raise_for_status
    raise HTTPError(http_error_msg, response=self)
requests.exceptions.HTTPError: 400 Client Error: Bad Request for url: https://restcountries.com/v3.1/all
[2025-07-23T09:40:55.118+0000] {taskinstance.py:1138} INFO - Marking task as FAILED. dag_id=rest_countries_dag, task_id=fetch_countries, execution_date=20250723T093552, start_date=20250723T094054, end_date=20250723T094055
[2025-07-23T09:40:55.125+0000] {standard_task_runner.py:107} ERROR - Failed to execute job 76 for task fetch_countries (400 Client Error: Bad Request for url: https://restcountries.com/v3.1/all; 4796)
[2025-07-23T09:40:55.173+0000] {local_task_job_runner.py:234} INFO - Task exited with return code 1
[2025-07-23T09:40:55.187+0000] {taskinstance.py:3280} INFO - 0 downstream tasks scheduled from follow-on schedule check
